Workbook

Sheet はじめに
B3: NLPコーチング ワークシート
B4: 代表システム優先度テスト ＋ 望むこと100個 リスト
B7: 📘 このワークシートの使い方
B9: ① 代表システム優先度テスト
B10: あなたが世界を捉えるとき、視覚(V) / 聴覚(A) / 身体感覚(K) / 内部対話(Ad) のどの感覚を優位に使っているかを診断します。各設問の4つの選択肢に 4・3・2・1 を1回ずつ入力してください（同点不可）。
B12: ② バランス車輪
B13: 人生の8つの領域について、現在の満足度を 0〜10 で自己評価します。人生全体のバランスを可視化するステップです。
B15: ③ テーマ別 望むこと
B16: 各テーマごとに「将来どうなりたいか」「望むこと」を書き出します。記入した内容は自動的に「望むこと100個」シートに集約されます。
B18: ④ 望むこと100個
B19: テーマ別シートに入力した内容が、100個のリストとして自動で集約・表示されます。人生全体の理想像の一覧です。
B22: 📌 進め方のヒント ・順番にこだわらず、書きやすいテーマから始めて構いません。 ・「すでにそうなった」気持ちで、過去形・断定形で書くと潜在意識に届きやすくなります。 ・1テーマあたり平均6〜8個を目安に。100個に届かなくても大丈夫です、思いついた数で進めましょう。

Sheet ①代表システム優先度テスト
B2: 代表システム 優先度テスト
B3: 各設問の4つの選択肢に対し、あなたに当てはまる度合いで「4 / 3 / 2 / 1」をそれぞれ1回ずつ入力してください（同点不可）。 4=もっともあてはまる ／ 3=あてはまる ／ 2=ややあてはまる ／ 1=すこしあてはまる
B5: 設問 | C5: 選択肢 | D5: 得点（1〜4） | E5: タイプ
A6: 1 | B6: 問1 私は、大切な決定を＿＿＿を基に決めています。 | C6: そのとき受けている感じの具合 | E6: K
C7: どれが一番よい響きに聞こえるか | E7: A
C8: どれが最もよいビジョンが描けるか | E8: V
C9: 正確に調べテーマを吟味すること | E9: Ad
A11: 2 | B11: 問2 議論の間、私が最も影響を受けやすいのは | C11: 他の人が話す時の声の大きさや調子 | E11: A
C12: 他の人の話の概要がハッキリと見えるかどうか | E12: V
C13: 他の人の話の筋道や論理 | E13: Ad
C14: 他の人の気持ちや内容に共感できるかどうか | E14: K
A16: 3 | B16: 問3 私が自分の状態を一番気づきやすいのは | C16: 自分がどんな服を着て、見栄えはどうかによって | E16: V
C17: 自分がどんな雰囲気になっているかによって | E17: K
C18: 自分が話の中で意識する言葉づかいや内容によって | E18: Ad
C19: 自分が話す時の声の調子によって | E19: A
A21: 4 | B21: 問4 私にとって、最も簡単にできそうなのは | C21: ステレオなどで好みの音質を見つけたりテレビの音量を気にすること | E21: A
C22: 興味ある事柄に関連した知識や情報を集めること | E22: Ad
C23: 一番快適で座り心地の良いソファーを探し出すこと | E23: K
C24: 美しく、魅力的な色の配色を選び出すこと | E24: V
A26: 5 | B26: 問5 私は・・・ | C26: 私は自分のいる場所の音やざわめきが気になります | E26: A
C27: 私は新しい情報やデータをよく知っていることに関心があります | E27: Ad
C28: 私は自分に触れる椅子や布団の肌触りが気になります | E28: K
C29: 私は自分の部屋の片づけ具合や色の配色に関心があります | E29: V
B32: 📊 タイプ別 集計（自動計算）
C33: タイプ | D33: 合計点 | E33: 比率
C34: V（Visual）視覚型 | D34: =SUM(D8,D12,D16,D24,D29) | E34: =IF(SUM($D$34:$D$37)=0,0,D34/SUM($D$34:$D$37))
C35: A（Auditory）聴覚型 | D35: =SUM(D7,D11,D19,D21,D26) | E35: =IF(SUM($D$34:$D$37)=0,0,D35/SUM($D$34:$D$37))
C36: K（Kinesthetic）身体感覚型 | D36: =SUM(D6,D14,D17,D23,D28) | E36: =IF(SUM($D$34:$D$37)=0,0,D36/SUM($D$34:$D$37))
C37: Ad（Auditory Digital）内部対話型 | D37: =SUM(D9,D13,D18,D22,D27) | E37: =IF(SUM($D$34:$D$37)=0,0,D37/SUM($D$34:$D$37))
B39: 🏆 最優位タイプ | D39: =IF(SUM(D34:D37)=0,"未入力",INDEX($C$34:$C$37,MATCH(MAX($D$34:$D$37),$D$34:$D$37,0)))

Sheet ②優位感覚別 特徴
B2: 優位感覚別の特徴
B3: あなたの優位感覚を知ることで、自分の強みや、コーチング・対話で活かす切り口が見えてきます。
B5: V（Visual）視覚型
B6: ・ 一般に背筋が伸びた良い姿勢
B7: ・ 目がよく上に動く
B8: ・ 話すテンポが速い
B9: ・ 声のトーンが高い
B10: ・ 話を視覚的な表現で好む
B11: ・ 外見を重視する
B12: ・ 呼吸は胸の上部で浅め
B14: A（Auditory）聴覚型
B15: ・ 話すテンポはVとKの中間
... B38: ・ 独り言を言ったり自分の中で対話する

Sheet ③バランス車輪
B2: 人生のバランス車輪
B3: ・人生の8つの領域のバランスを見ます。「0〜10」で満足度を自己評価してください。 ・現在の状態を記入してOKです。1ヶ月後・1年後・3年後など、将来の目標値としても活用できます。
C5: 大テーマ | D5: 平均値 | E5: 小テーマ | F5: 満足度（0〜10）
B6: 1 | C6: 仕事・キャリア | D6: =IFERROR(AVERAGE(F6:F7),"") | E6: やりがい
E7: 収入
B8: 2 | C8: お金・経済 | D8: =IFERROR(AVERAGE(F8:F9),"") | E8: 貯蓄
E9: 投資
B10: 3 | C10: 健康 | D10: =IFERROR(AVERAGE(F10:F11),"") | E10: 身体
E11: メンタル
B12: 4 | C12: 家族・パートナー | D12: =IFERROR(AVERAGE(F12:F13),"") | E12: 家族
E13: パートナー
B14: 5 | C14: 人間関係 | D14: =IFERROR(AVERAGE(F14:F15),"") | E14: 友人・知人
E15: 仕事関係
B16: 6 | C16: 精神性 | D16: =IFERROR(AVERAGE(F16:F17),"") | E16: ミッション
E17: 学び
B18: 7 | C18: 遊び・余暇 | D18: =IFERROR(AVERAGE(F18:F19),"") | E18: 行きたい所
E19: 欲しいもの
B20: 8 | C20: 環境 | D20: =IFERROR(AVERAGE(F20:F21),"") | E20: 住居
E21: 環境
B24: 🎯 バランス車輪 ビジュアル化
B25: テーマ | C25: 平均値
B26: 仕事・キャリア | C26: =IFERROR(D6,0)
B27: お金・経済 | C27: =IFERROR(D8,0)
B28: 健康 | C28: =IFERROR(D10,0)
B29: 家族・パートナー | C29: =IFERROR(D12,0)
B30: 人間関係 | C30: =IFERROR(D14,0)
B31: 精神性 | C31: =IFERROR(D16,0)
B32: 遊び・余暇 | C32: =IFERROR(D18,0)
B33: 環境 | C33: =IFERROR(D20,0)

Sheet ④テーマ別 望むこと
B2: テーマ別 望むこと
B3: 各テーマの小テーマごとに、将来「こうなっていたい」望みを書き出します。 📌 ヒント：「すでに実現した」気持ちで、過去形・断定形で書くと効果的です。1テーマ平均6〜8個が目安。
B5: 仕事・キャリア | G5: お金・経済
B6: # | C6: やりがい | D6: # | E6: 収入 | G6: # | H6: 貯蓄 | I6: # | J6: 投資
B7: 1 | D7: 1 | G7: 1 | I7: 1
B8: 2 | D8: 2 | G8: 2 | I8: 2
B9: 3 | D9: 3 | G9: 3 | I9: 3
B10: 4 | D10: 4 | G10: 4 | I10: 4
B11: 5 | D11: 5 | G11: 5 | I11: 5
B12: 6 | D12: 6 | G12: 6 | I12: 6
B13: 7 | D13: 7 | G13: 7 | I13: 7
B14: 8 | D14: 8 | G14: 8 | I14: 8
B15: 9 | D15: 9 | G15: 9 | I15: 9
B16: 10 | D16: 10 | G16: 10 | I16: 10
B18: 健康 | G18: 家族・パートナー
B19: # | C19: 身体 | D19: # | E19: メンタル | G19: # | H19: 家族 | I19: # | J19: パートナー
B20: 1 | D20: 1 | G20: 1 | I20: 1
B21: 2 | D21: 2 | G21: 2 | I21: 2
B22: 3 | D22: 3 | G22: 3 | I22: 3
B23: 4 | D23: 4 | G23: 4 | I23: 4
B24: 5 | D24: 5 | G24: 5 | I24: 5
B25: 6 | D25: 6 | G25: 6 | I25: 6
B26: 7 | D26: 7 | G26: 7 | I26: 7
B27: 8 | D27: 8 | G27: 8 | I27: 8
B28: 9 | D28: 9 | G28: 9 | I28: 9
B29: 10 | D29: 10 | G29: 10 | I29: 10
B31: 人間関係 | G31: 精神性
B32: # | C32: 友人・知人 | D32: # | E32: 仕事関係 | G32: # | H32: ミッション | I32: # | J32: 学び
B33: 1 | D33: 1 | G33: 1 | I33: 1
B34: 2 | D34: 2 | G34: 2 | I34: 2
B35: 3 | D35: 3 | G35: 3 | I35: 3
B36: 4 | D36: 4 | G36: 4 | I36: 4
B37: 5 | D37: 5 | G37: 5 | I37: 5
B38: 6 | D38: 6 | G38: 6 | I38: 6
B39: 7 | D39: 7 | G39: 7 | I39: 7
B40: 8 | D40: 8 | G40: 8 | I40: 8
B41: 9 | D41: 9 | G41: 9 | I41: 9
B42: 10 | D42: 10 | G42: 10 | I42: 10
B44: 遊び・余暇 | G44: 環境
B45: # | C45: 行きたい所 | D45: # | E45: 欲しいもの | G45: # | H45: 住居 | I45: # | J45: 環境
...

Sheet ⑤望むこと100個
B2: 望むこと 100個
B3: ④テーマ別シートに入力した「望むこと」が、ここに自動で集約されます。
B5: No. | C5: 大テーマ | D5: 小テーマ | E5: 望むこと
B6: 1 | C6: 仕事・キャリア | D6: やりがい | E6: ='④テーマ別 望むこと'!C7
B7: 2 | C7: 仕事・キャリア | D7: 収入 | E7: ='④テーマ別 望むこと'!E7
B8: 3 | C8: 仕事・キャリア | D8: やりがい | E8: ='④テーマ別 望むこと'!C8
B9: 4 | C9: 仕事・キャリア | D9: 収入 | E9: ='④テーマ別 望むこと'!E8
B10: 5 | C10: 仕事・キャリア | D10: やりがい | E10: ='④テーマ別 望むこと'!C9
B11: 6 | C11: 仕事・キャリア | D11: 収入 | E11: ='④テーマ別 望むこと'!E9
B12: 7 | C12: 仕事・キャリア | D12: やりがい | E12: ='④テーマ別 望むこと'!C10
B13: 8 | C13: 仕事・キャリア | D13: 収入 | E13: ='④テーマ別 望むこと'!E10
B14: 9 | C14: 仕事・キャリア | D14: やりがい | E14: ='④テーマ別 望むこと'!C11
B15: 10 | C15: 仕事・キャリア | D15: 収入 | E15: ='④テーマ別 望むこと'!E11
B16: 11 | C16: 仕事・キャリア | D16: やりがい | E16: ='④テーマ別 望むこと'!C12
B17: 12 | C17: 仕事・キャリア | D17: 収入 | E17: ='④テーマ別 望むこと'!E12
B18: 13 | C18: 仕事・キャリア | D18: やりがい | E18: ='④テーマ別 望むこと'!C13
B19: 14 | C19: 仕事・キャリア | D19: 収入 | E19: ='④テーマ別 望むこと'!E13
B20: 15 | C20: 仕事・キャリア | D20: やりがい | E20: ='④テーマ別 望むこと'!C14
B21: 16 | C21: 仕事・キャリア | D21: 収入 | E21: ='④テーマ別 望むこと'!E14
B22: 17 | C22: 仕事・キャリア | D22: やりがい | E22: ='④テーマ別 望むこと'!C15
B23: 18 | C23: 仕事・キャリア | D23: 収入 | E23: ='④テーマ別 望むこと'!E15
B24: 19 | C24: 仕事・キャリア | D24: やりがい | E24: ='④テーマ別 望むこと'!C16
B25: 20 | C25: 仕事・キャリア | D25: 収入 | E25: ='④テーマ別 望むこと'!E16
B26: 21 | C26: お金・経済 | D26: 貯蓄 | E26: ='④テーマ別 望むこと'!H7
B27: 22 | C27: お金・経済 | D27: 投資 | E27: ='④テーマ別 望むこと'!J7
B28: 23 | C28: お金・経済 | D28: 貯蓄 | E28: ='④テーマ別 望むこと'!H8
B29: 24 | C29: お金・経済 | D29: 投資 | E29: ='④テーマ別 望むこと'!J8
B30: 25 | C30: お金・経済 | D30: 貯蓄 | E30: ='④テーマ別 望むこと'!H9
B31: 26 | C31: お金・経済 | D31: 投資 | E31: ='④テーマ別 望むこと'!J9
B32: 27 | C32: お金・経済 | D32: 貯蓄 | E32: ='④テーマ別 望むこと'!H10
B33: 28 | C33: お金・経済 | D33: 投資 | E33: ='④テーマ別 望むこと'!J10
B34: 29 | C34: お金・経済 | D34: 貯蓄 | E34: ='④テーマ別 望むこと'!H11
B35: 30 | C35: お金・経済 | D35: 投資 | E35: ='④テーマ別 望むこと'!J11
B36: 31 | C36: お金・経済 | D36: 貯蓄 | E36: ='④テーマ別 望むこと'!H12
B37: 32 | C37: お金・経済 | D37: 投資 | E37: ='④テーマ別 望むこと'!J12
B38: 33 | C38: お金・経済 | D38: 貯蓄 | E38: ='④テーマ別 望むこと'!H13
B39: 34 | C39: お金・経済 | D39: 投資 | E39: ='④テーマ別 望むこと'!J13
B40: 35 | C40: お金・経済 | D40: 貯蓄 | E40: ='④テーマ別 望むこと'!H14
B41: 36 | C41: お金・経済 | D41: 投資 | E41: ='④テーマ別 望むこと'!J14
B42: 37 | C42: お金・経済 | D42: 貯蓄 | E42: ='④テーマ別 望むこと'!H15
...
