Workbook

Sheet 使用方法
B2: 📘 使用方法マニュアル（望むこと100個リスト作成用スプレッドシート）
B3: 1. シート構成
B4: ① バランス車輪
B5: 人生の各領域について、現在の満足度を 0〜10 で自己評価します。
B6: 「大テーマ（例：仕事・キャリア／お金・経済／健康…）」に加えて、
B7: 「小テーマ（例：やりがい・収入・貯蓄など）」ごとに記入します。
B8: 👉 人生全体のバランスを可視化するステップです。
B10: ② テーマ別望むこと
B11: 各テーマごとに「将来どうなりたいか」「望むこと」を書き出します。
B12: 👉 記入した望みは自動的に次のシートへ転送されます。
B14: ③ 望むこと100個
B15: 「テーマ別望むこと」に入力した内容が集約され、100個のリストとして完成します。
... B40: - 成長の確認：定期的に見返すことで、実現できたことや変化を振り返れる。

Sheet ①バランス車輪
B1: 人生のバランス車輪
B3: ・人生の領域のバランスを見る 「0〜10」満足度の自己評価をする
B4: ・現在、1ヶ月後、1年後、3年後・・・10年後など、将来どうなっていたいのか？
B5: （将来の理想や予測にも活用できる）
B8: 大テーマ | C8: 平均値 | D8: 小テーマ | E8: 満足度
B9: 仕事・キャリア | C9: =(E9+E10)/2 -> 0 | D9: やりがい
D10: 収入
B11: お金・経済 | C11: =(E11+E12)/2 -> 0 | D11: 貯蓄
D12: 投資
B13: 健康 | C13: =(E13+E14)/2 -> 0 | D13: 身体
D14: メンタル
B15: 家族・パートナー | C15: =(E15+E16)/2 -> 0 | D15: 家族
D16: パートナー
B17: 人間関係 | C17: =(E17+E18)/2 -> 0 | D17: 友人・知人
D18: 仕事関係
B19: 精神性 | C19: =(E19+E20)/2 -> 0 | D19: ミッション
D20: 学び
B21: 遊び・余暇 | C21: =(E21+E22)/2 -> 0 | D21: 行きたい所
D22: 欲しいもの
B23: 環境 | C23: =(E23+E24)/2 -> 0 | D23: 住居
D24: 環境

Sheet ②テーマ別望むこと
B1: バランス車輪テーマ別望むこと
B3: ・現在、1ヶ月後、1年後、3年後・・・10年後など、将来どうなっていたいのか？
B4: ・各テーマごとに望む事を記入すると、「望むこと100個」のシートにリスト化します。
B6: 仕事・キャリア | F6: お金・経済
B7: やりがい | D7: 収入 | F7: 貯蓄 | H7: 投資
B8: 1 | D8: 1 | F8: 1 | H8: 1 | K8: =C8 -> 0
B9: 2 | D9: 2 | F9: 2 | H9: 2 | K9: =C9 -> 0
B10: 3 | D10: 3 | F10: 3 | H10: 3 | K10: =C10 -> 0
B11: 4 | D11: 4 | F11: 4 | H11: 4 | K11: =C11 -> 0
B12: 5 | D12: 5 | F12: 5 | H12: 5 | K12: =C12 -> 0
B13: 6 | D13: 6 | F13: 6 | H13: 6 | K13: =C13 -> 0
B14: 7 | D14: 7 | F14: 7 | H14: 7 | K14: =C14 -> 0
B15: 8 | D15: 8 | F15: 8 | H15: 8 | K15: =C15 -> 0
B16: 9 | D16: 9 | F16: 9 | H16: 9 | K16: =C16 -> 0
B17: 10 | D17: 10 | F17: 10 | H17: 10 | K17: =C17 -> 0
K18: =E8 -> 0
B19: 健康 | F19: 家族・パートナー | K19: =E9 -> 0
B20: 身体 | D20: メンタル | F20: 家族 | H20: パートナー | K20: =E10 -> 0
B21: 1 | D21: 1 | F21: 1 | H21: 1 | K21: =E11 -> 0
B22: 2 | D22: 2 | F22: 2 | H22: 2 | K22: =E12 -> 0
B23: 3 | D23: 3 | F23: 3 | H23: 3 | K23: =E13 -> 0
B24: 4 | D24: 4 | F24: 4 | H24: 4 | K24: =E14 -> 0
B25: 5 | D25: 5 | F25: 5 | H25: 5 | K25: =E15 -> 0
B26: 6 | D26: 6 | F26: 6 | H26: 6 | K26: =E16 -> 0
B27: 7 | D27: 7 | F27: 7 | H27: 7 | K27: =E17 -> 0
B28: 8 | D28: 8 | F28: 8 | H28: 8 | K28: =G8 -> 0
B29: 9 | D29: 9 | F29: 9 | H29: 9 | K29: =G9 -> 0
B30: 10 | D30: 10 | F30: 10 | H30: 10 | K30: =G10 -> 0
K31: =G11 -> 0
B32: 人間関係 | F32: 精神性 | K32: =G12 -> 0
B33: 友人・知人 | D33: 仕事関係 | F33: ミッション | H33: 学び | K33: =G13 -> 0
B34: 1 | D34: 1 | F34: 1 | H34: 1 | K34: =G14 -> 0
B35: 2 | D35: 2 | F35: 2 | H35: 2 | K35: =G15 -> 0
B36: 3 | D36: 3 | F36: 3 | H36: 3 | K36: =G16 -> 0
B37: 4 | D37: 4 | F37: 4 | H37: 4 | K37: =G17 -> 0
B38: 5 | D38: 5 | F38: 5 | H38: 5 | K38: =I8 -> 0
B39: 6 | D39: 6 | F39: 6 | H39: 6 | K39: =I9 -> 0
B40: 7 | D40: 7 | F40: 7 | H40: 7 | K40: =I10 -> 0
B41: 8 | D41: 8 | F41: 8 | H41: 8 | K41: =I11 -> 0
B42: 9 | D42: 9 | F42: 9 | H42: 9 | K42: =I12 -> 0
...

Sheet ③望むこと１００個
B1: 望むこと100個
B3: 1 | C3: {=_xlfn.LET( _xlpm.src, ②テーマ別望むこと!K8:K167, _xlpm.vals, _xlfn._xlws.FILTER(_xlpm.src, (_xlpm.src<>"")*ISTEXT(_xlpm.src), ""), INDEX(_xlpm.vals, _xlfn.SEQUENCE(MIN(ROWS(_xlpm.vals),100))) )}
B4: 2
B5: 3
B6: 4
B7: 5
B8: 6
B9: 7
B10: 8
B11: 9
B12: 10
B13: 11
B14: 12
B15: 13
... B102: 100
